<?xml version="1.0" encoding="utf-8"?>
<robot name="myrobot">
    <link name="shoulder_link">
        <inertial>
            <mass value="3.70000000"/>
            <origin xyz="0.00000000 0.00000000 0.00000000"/>
            <inertia ixx="0.01026750" ixy="0.00000000" ixz="0.00000000" iyy="0.01026750" iyz="0.00000000" izz="0.00666000"/>
        </inertial>
        <visual>
            <origin xyz="0.00000000 0.00000000 0.00000000" rpy="0.00000000 0.00000000 0.00000000"/>
            <geometry>
                <mesh filename="package://ur5_description/meshes/ur5/visual/shoulder.dae"/>
            </geometry>
            <material name="LightGrey">
                <color rgba="0.70000000 0.70000000 0.70000000 1.00000000"/>
            </material>
        </visual>
        <collision>
            <origin xyz="0.00000000 0.00000000 0.00000000" rpy="0.00000000 0.00000000 0.00000000"/>
            <geometry>
                <mesh filename="package://ur5_description/meshes/ur5/collision/shoulder.stl"/>
            </geometry>
        </collision>
    </link>
    <link name="upper_arm_link">
        <inertial>
            <mass value="8.39300000"/>
            <origin xyz="0.00000000 0.00000000 0.28000000"/>
            <inertia ixx="0.22689068" ixy="0.00000000" ixz="0.00000000" iyy="0.22689068" iyz="0.00000000" izz="0.01510740"/>
        </inertial>
        <visual>
            <origin xyz="0.00000000 0.00000000 0.00000000" rpy="0.00000000 0.00000000 0.00000000"/>
            <geometry>
                <mesh filename="package://ur5_description/meshes/ur5/visual/upperarm.dae"/>
            </geometry>
            <material name="LightGrey">
                <color rgba="0.70000000 0.70000000 0.70000000 1.00000000"/>
            </material>
        </visual>
        <collision>
            <origin xyz="0.00000000 0.00000000 0.00000000" rpy="0.00000000 0.00000000 0.00000000"/>
            <geometry>
                <mesh filename="package://ur5_description/meshes/ur5/collision/upperarm.stl"/>
            </geometry>
        </collision>
    </link>
    <link name="forearm_link">
        <inertial>
            <mass value="2.27500000"/>
            <origin xyz="0.00000000 0.00000000 0.25000000"/>
            <inertia ixx="0.04944331" ixy="0.00000000" ixz="0.00000000" iyy="0.04944331" iyz="0.00000000" izz="0.00409500"/>
        </inertial>
        <visual>
            <origin xyz="0.00000000 0.00000000 0.00000000" rpy="0.00000000 0.00000000 0.00000000"/>
            <geometry>
                <mesh filename="package://ur5_description/meshes/ur5/visual/forearm.dae"/>
            </geometry>
            <material name="LightGrey">
                <color rgba="0.70000000 0.70000000 0.70000000 1.00000000"/>
            </material>
        </visual>
        <collision>
            <origin xyz="0.00000000 0.00000000 0.00000000" rpy="0.00000000 0.00000000 0.00000000"/>
            <geometry>
                <mesh filename="package://ur5_description/meshes/ur5/collision/forearm.stl"/>
            </geometry>
        </collision>
    </link>
    <link name="wrist_1_link">
        <inertial>
            <mass value="1.21900000"/>
            <origin xyz="0.00000000 0.00000000 0.00000000"/>
            <inertia ixx="0.11117276" ixy="0.00000000" ixz="0.00000000" iyy="0.11117276" iyz="0.00000000" izz="0.21942000"/>
        </inertial>
        <visual>
            <origin xyz="0.00000000 0.00000000 0.00000000" rpy="0.00000000 0.00000000 0.00000000"/>
            <geometry>
                <mesh filename="package://ur5_description/meshes/ur5/visual/wrist1.dae"/>
            </geometry>
            <material name="LightGrey">
                <color rgba="0.70000000 0.70000000 0.70000000 1.00000000"/>
            </material>
        </visual>
        <collision>
            <origin xyz="0.00000000 0.00000000 0.00000000" rpy="0.00000000 0.00000000 0.00000000"/>
            <geometry>
                <mesh filename="package://ur5_description/meshes/ur5/collision/wrist1.stl"/>
            </geometry>
        </collision>
    </link>
    <link name="wrist_2_link">
        <inertial>
            <mass value="1.21900000"/>
            <origin xyz="0.00000000 0.00000000 0.00000000"/>
            <inertia ixx="0.11117276" ixy="0.00000000" ixz="0.00000000" iyy="0.11117276" iyz="0.00000000" izz="0.21942000"/>
        </inertial>
        <visual>
            <origin xyz="0.00000000 0.00000000 0.00000000" rpy="0.00000000 0.00000000 0.00000000"/>
            <geometry>
                <mesh filename="package://ur5_description/meshes/ur5/visual/wrist2.dae"/>
            </geometry>
            <material name="LightGrey">
                <color rgba="0.70000000 0.70000000 0.70000000 1.00000000"/>
            </material>
        </visual>
        <collision>
            <origin xyz="0.00000000 0.00000000 0.00000000" rpy="0.00000000 0.00000000 0.00000000"/>
            <geometry>
                <mesh filename="package://ur5_description/meshes/ur5/collision/wrist2.stl"/>
            </geometry>
        </collision>
    </link>
    <link name="wrist_3_link">
        <inertial>
            <mass value="0.18790000"/>
            <origin xyz="0.00000000 0.00000000 0.00000000"/>
            <inertia ixx="0.01713647" ixy="0.00000000" ixz="0.00000000" iyy="0.01713647" iyz="0.00000000" izz="0.03382200"/>
        </inertial>
        <visual>
            <origin xyz="0.00000000 0.00000000 0.00000000" rpy="0.00000000 0.00000000 0.00000000"/>
            <geometry>
                <mesh filename="package://ur5_description/meshes/ur5/visual/wrist3.dae"/>
            </geometry>
            <material name="LightGrey">
                <color rgba="0.70000000 0.70000000 0.70000000 1.00000000"/>
            </material>
        </visual>
        <collision>
            <origin xyz="0.00000000 0.00000000 0.00000000" rpy="0.00000000 0.00000000 0.00000000"/>
            <geometry>
                <mesh filename="package://ur5_description/meshes/ur5/collision/wrist3.stl"/>
            </geometry>
        </collision>
    </link>
    <link name="base_link">
        <inertial>
            <mass value="4.00000000"/>
            <origin xyz="0.00000000 0.00000000 0.00000000"/>
            <inertia ixx="0.00443333" ixy="0.00000000" ixz="0.00000000" iyy="0.00443333" iyz="0.00000000" izz="0.00720000"/>
        </inertial>
    </link>
    <link name="base"/>
    <link name="ee_link"/>
    <link name="tool0"/>
    <link name="__ARB_BASE__"/>
    <joint name="joint_1" type="revolute">
        <origin xyz="0.00000000 0.00000000 0.08915900" rpy="0.00000000 -0.00000000 0.00000000"/>
        <parent link="__ARB_BASE__"/>
        <child link="shoulder_link"/>
        <axis xyz="0.00000000 0.00000000 1.00000000"/>
        <limit lower="-3.14159265" upper="3.14159265" effort="150.00000000" velocity="3.15000000"/>
        <dynamics damping="0.00000000" friction="0.00000000"/>
    </joint>
    <joint name="joint_2" type="revolute">
        <origin xyz="0.00000000 0.13585000 0.00000000" rpy="0.00000000 1.57079633 0.00000000"/>
        <parent link="shoulder_link"/>
        <child link="upper_arm_link"/>
        <axis xyz="0.00000000 1.00000000 0.00000000"/>
        <limit lower="-3.14159265" upper="3.14159265" effort="150.00000000" velocity="3.15000000"/>
        <dynamics damping="0.00000000" friction="0.00000000"/>
    </joint>
    <joint name="joint_3" type="revolute">
        <origin xyz="0.00000000 -0.11970000 0.42500000" rpy="0.00000000 -0.00000000 0.00000000"/>
        <parent link="upper_arm_link"/>
        <child link="forearm_link"/>
        <axis xyz="0.00000000 1.00000000 0.00000000"/>
        <limit lower="-3.14159265" upper="3.14159265" effort="150.00000000" velocity="3.15000000"/>
        <dynamics damping="0.00000000" friction="0.00000000"/>
    </joint>
    <joint name="joint_4" type="revolute">
        <origin xyz="0.00000000 0.00000000 0.39225000" rpy="0.00000000 1.57079633 0.00000000"/>
        <parent link="forearm_link"/>
        <child link="wrist_1_link"/>
        <axis xyz="0.00000000 1.00000000 0.00000000"/>
        <limit lower="-3.14159265" upper="3.14159265" effort="28.00000000" velocity="3.20000000"/>
        <dynamics damping="0.00000000" friction="0.00000000"/>
    </joint>
    <joint name="joint_5" type="revolute">
        <origin xyz="0.00000000 0.09300000 0.00000000" rpy="0.00000000 -0.00000000 0.00000000"/>
        <parent link="wrist_1_link"/>
        <child link="wrist_2_link"/>
        <axis xyz="0.00000000 0.00000000 1.00000000"/>
        <limit lower="-3.14159265" upper="3.14159265" effort="28.00000000" velocity="3.20000000"/>
        <dynamics damping="0.00000000" friction="0.00000000"/>
    </joint>
    <joint name="joint_6" type="revolute">
        <origin xyz="0.00000000 0.00000000 0.09465000" rpy="0.00000000 -0.00000000 0.00000000"/>
        <parent link="wrist_2_link"/>
        <child link="wrist_3_link"/>
        <axis xyz="0.00000000 1.00000000 0.00000000"/>
        <limit lower="-3.14159265" upper="3.14159265" effort="28.00000000" velocity="3.20000000"/>
        <dynamics damping="0.00000000" friction="0.00000000"/>
    </joint>
    <joint name="fixed_joint_0" type="fixed">
        <origin xyz="0.00000000 0.00000000 0.00000000" rpy="0.00000000 -0.00000000 0.00000000"/>
        <parent link="__ARB_BASE__"/>
        <child link="base_link"/>
        <axis xyz="1.00000000 0.00000000 0.00000000"/>
        <dynamics damping="0.00000000" friction="0.00000000"/>
    </joint>
    <joint name="fixed_joint_1" type="fixed">
        <origin xyz="0.00000000 0.00000000 0.00000000" rpy="0.00000000 -0.00000000 3.14159265"/>
        <parent link="__ARB_BASE__"/>
        <child link="base"/>
        <axis xyz="1.00000000 0.00000000 0.00000000"/>
        <dynamics damping="0.00000000" friction="0.00000000"/>
    </joint>
    <joint name="fixed_joint_2" type="fixed">
        <origin xyz="0.00000000 0.08230000 0.00000000" rpy="0.00000000 -0.00000000 1.57079633"/>
        <parent link="wrist_3_link"/>
        <child link="ee_link"/>
        <axis xyz="1.00000000 0.00000000 0.00000000"/>
        <dynamics damping="0.00000000" friction="0.00000000"/>
    </joint>
    <joint name="fixed_joint_3" type="fixed">
        <origin xyz="0.00000000 0.08230000 0.00000000" rpy="-1.57079633 0.00000000 0.00000000"/>
        <parent link="wrist_3_link"/>
        <child link="tool0"/>
        <axis xyz="1.00000000 0.00000000 0.00000000"/>
        <dynamics damping="0.00000000" friction="0.00000000"/>
    </joint>
</robot>
